Workbook

Sheet README
A1: Carbon Footprint Dataset — Apple Inc.
A2: Real, publicly disclosed Scope 1 / 2 / 3 greenhouse gas emissions, FY2015–FY2022
A4: Source | B4: Apple Inc. Environmental Progress Reports (2016–2023 editions)
A5: Original publisher | B5: Apple.com — apple.com/environment
A6: Compiled by | B6: Maven Analytics Data Playground (mavenanalytics.io/data-playground)
A7: License | B7: Public Domain
A8: Units | B8: Metric tons CO2 equivalent (CO2e), unless noted otherwise
A9: Fiscal year note | B9: Apple's fiscal year starts the last Sunday of September and runs 364 days
A11: Sheet: Raw_GHG_Emissions | B11: 136 line items — every disclosed emissions source by year, category, type, and scope (1/2/3)
A12: Sheet: Yearly_Scope_Summary | B12: Pivoted totals by fiscal year and scope, computed with live SUMIFS formulas from the raw sheet
A13: Sheet: Carbon_Footprint_by_Product | B13: Life-cycle carbon footprint (kg CO2e) of each baseline iPhone model, 2015–2023
A14: Sheet: Normalizing_Factors | B14: Apple's revenue, market capitalization, and headcount by fiscal year — for intensity ratios
A16: Known data gaps | B16: Several Scope 3 corporate sub-categories (e.g. upstream fuel, work-from-home, third-party cloud) were not separately disclosed before FY2018–2019 — these cells are blank in the source, not estimated.
A17: Use in your project | B17: Good as a real, verified anchor dataset for a single company's Scope 1/2/3 trend. For a multi-company supply-chain training set, combine with Climate TRACE (climatetrace.org/data) or additional company CDP disclosures.

Sheet Raw_GHG_Emissions
A1: Fiscal Year | B1: Category | C1: Type | D1: Scope | E1: Description | F1: Emissions (metric tons CO2e)
A2: 2022 | B2: Corporate emissions | C2: Gross emissions | D2: Scope 1 | E2: Natural gas, diesel, propane | F2: 39700
A3: 2022 | B3: Corporate emissions | C3: Gross emissions | D3: Scope 1 | E3: Fleet vehicles | F3: 12600
A4: 2022 | B4: Corporate emissions | C4: Gross emissions | D4: Scope 1 | E4: Other (R&D processes & refrigerant leaks) | F4: 2900
A5: 2022 | B5: Corporate emissions | C5: Gross emissions | D5: Scope 2 (market-based) | E5: Electricity | F5: 0
A6: 2022 | B6: Corporate emissions | C6: Gross emissions | D6: Scope 2 (market-based) | E6: Steam, heating, and cooling | F6: 3000
A7: 2022 | B7: Corporate emissions | C7: Gross emissions | D7: Scope 3 | E7: Business travel | F7: 113500
A8: 2022 | B8: Corporate emissions | C8: Gross emissions | D8: Scope 3 | E8: Employee commute | F8: 134200
A9: 2022 | B9: Corporate emissions | C9: Gross emissions | D9: Scope 3 | E9: Upstream fuel | F9: 10600
A10: 2022 | B10: Corporate emissions | C10: Gross emissions | D10: Scope 3 | E10: Work from home (market-based) | F10: 7500
A11: 2022 | B11: Corporate emissions | C11: Gross emissions | D11: Scope 3 | E11: Transmission and distribution loss (market-based) | F11: 0
A12: 2022 | B12: Corporate emissions | C12: Gross emissions | D12: Scope 3 | E12: Third-party cloud (market-based) | F12: 0
A13: 2022 | B13: Corporate emissions | C13: Carbon removals | E13: Corporate carbon offsets | F13: -324100
A14: 2022 | B14: Product life cycle emissions | C14: Gross emissions | D14: Scope 3 | E14: Manufacturing (purchased goods and services) | F14: 13400000
A15: 2022 | B15: Product life cycle emissions | C15: Gross emissions | D15: Scope 3 | E15: Product transportation (upstream and downstream) | F15: 1900000
A16: 2022 | B16: Product life cycle emissions | C16: Gross emissions | D16: Scope 3 | E16: Product use (use of sold products) | F16: 4900000
A17: 2022 | B17: Product life cycle emissions | C17: Gross emissions | D17: Scope 3 | E17: End-of-life processing | F17: 80000
A18: 2022 | B18: Product life cycle emissions | C18: Carbon removals | E18: Product carbon offsets | F18: 0
A19: 2021 | B19: Corporate emissions | C19: Gross emissions | D19: Scope 1 | E19: Natural gas, diesel, propane | F19: 40070
A20: 2021 | B20: Corporate emissions | C20: Gross emissions | D20: Scope 1 | E20: Fleet vehicles | F20: 12090
A21: 2021 | B21: Corporate emissions | C21: Gross emissions | D21: Scope 1 | E21: Other (R&D processes & refrigerant leaks) | F21: 3040
A22: 2021 | B22: Corporate emissions | C22: Gross emissions | D22: Scope 2 (market-based) | E22: Electricity | F22: 0
A23: 2021 | B23: Corporate emissions | C23: Gross emissions | D23: Scope 2 (market-based) | E23: Steam, heating, and cooling | F23: 2780
A24: 2021 | B24: Corporate emissions | C24: Gross emissions | D24: Scope 3 | E24: Business travel | F24: 22850
A25: 2021 | B25: Corporate emissions | C25: Gross emissions | D25: Scope 3 | E25: Employee commute | F25: 85570
A26: 2021 | B26: Corporate emissions | C26: Gross emissions | D26: Scope 3 | E26: Upstream fuel | F26: 0
A27: 2021 | B27: Corporate emissions | C27: Gross emissions | D27: Scope 3 | E27: Work from home (market-based) | F27: 0
A28: 2021 | B28: Corporate emissions | C28: Gross emissions | D28: Scope 3 | E28: Transmission and distribution loss (market-based)
A29: 2021 | B29: Corporate emissions | C29: Gross emissions | D29: Scope 3 | E29: Third-party cloud (market-based) | F29: 0
A30: 2021 | B30: Corporate emissions | C30: Carbon removals | E30: Corporate carbon offsets | F30: -167000
A31: 2021 | B31: Product life cycle emissions | C31: Gross emissions | D31: Scope 3 | E31: Manufacturing (purchased goods and services) | F31: 16200000
A32: 2021 | B32: Product life cycle emissions | C32: Gross emissions | D32: Scope 3 | E32: Product transportation (upstream and downstream) | F32: 1750000
A33: 2021 | B33: Product life cycle emissions | C33: Gross emissions | D33: Scope 3 | E33: Product use (use of sold products) | F33: 4990000
A34: 2021 | B34: Product life cycle emissions | C34: Gross emissions | D34: Scope 3 | E34: End-of-life processing | F34: 80000
A35: 2021 | B35: Product life cycle emissions | C35: Carbon removals | E35: Product carbon offsets | F35: -500000
A36: 2020 | B36: Corporate emissions | C36: Gross emissions | D36: Scope 1 | E36: Natural gas, diesel, propane | F36: 39340
A37: 2020 | B37: Corporate emissions | C37: Gross emissions | D37: Scope 1 | E37: Fleet vehicles | F37: 4270
A38: 2020 | B38: Corporate emissions | C38: Gross emissions | D38: Scope 1 | E38: Other (R&D processes & refrigerant leaks) | F38: 3830
A39: 2020 | B39: Corporate emissions | C39: Gross emissions | D39: Scope 2 (market-based) | E39: Electricity | F39: 0
A40: 2020 | B40: Corporate emissions | C40: Gross emissions | D40: Scope 2 (market-based) | E40: Steam, heating, and cooling | F40: 0
...

Sheet Yearly_Scope_Summary
A1: Fiscal Year | B1: Scope 1 (Gross) | C1: Scope 2 Market-Based (Gross) | D1: Scope 3 (Gross) | E1: Total Gross Emissions | F1: Carbon Removals (Offsets) | G1: Net Emissions
A2: 2015 | B2: =SUMIFS(Raw_GHG_Emissions!$F$2:$F$137,Raw_GHG_Emissions!$A$2:$A$137,A2,Raw_GHG_Emissions!$D$2:$D$137,"Scope 1",Raw_GHG_Emissions!$C$2:$C$137,"Gross emissions") -> 28100 | C2: =SUMIFS(Raw_GHG_Emissions!$F$2:$F$137,Raw_GHG_Emissions!$A$2:$A$137,A2,Raw_GHG_Emissions!$D$2:$D$137,"Scope 2 (market-based)",Raw_GHG_Emissions!$C$2:$C$137,"Gross emissions") -> 42460 | D2: =SUMIFS(Raw_GHG_Emissions!$F$2:$F$137,Raw_GHG_Emissions!$A$2:$A$137,A2,Raw_GHG_Emissions!$D$2:$D$137,"Scope 3",Raw_GHG_Emissions!$C$2:$C$137,"Gross emissions") -> 38312910 | E2: =SUM(B2:D2) -> 38383470 | F2: =SUMIFS(Raw_GHG_Emissions!$F$2:$F$137,Raw_GHG_Emissions!$A$2:$A$137,A2,Raw_GHG_Emissions!$C$2:$C$137,"Carbon removals") -> 0 | G2: =E2+F2 -> 38383470
A3: 2016 | B3: =SUMIFS(Raw_GHG_Emissions!$F$2:$F$137,Raw_GHG_Emissions!$A$2:$A$137,A3,Raw_GHG_Emissions!$D$2:$D$137,"Scope 1",Raw_GHG_Emissions!$C$2:$C$137,"Gross emissions") -> 34370 | C3: =SUMIFS(Raw_GHG_Emissions!$F$2:$F$137,Raw_GHG_Emissions!$A$2:$A$137,A3,Raw_GHG_Emissions!$D$2:$D$137,"Scope 2 (market-based)",Raw_GHG_Emissions!$C$2:$C$137,"Gross emissions") -> 41000 | D3: =SUMIFS(Raw_GHG_Emissions!$F$2:$F$137,Raw_GHG_Emissions!$A$2:$A$137,A3,Raw_GHG_Emissions!$D$2:$D$137,"Scope 3",Raw_GHG_Emissions!$C$2:$C$137,"Gross emissions") -> 29504000 | E3: =SUM(B3:D3) -> 29579370 | F3: =SUMIFS(Raw_GHG_Emissions!$F$2:$F$137,Raw_GHG_Emissions!$A$2:$A$137,A3,Raw_GHG_Emissions!$C$2:$C$137,"Carbon removals") -> 0 | G3: =E3+F3 -> 29579370
A4: 2017 | B4: =SUMIFS(Raw_GHG_Emissions!$F$2:$F$137,Raw_GHG_Emissions!$A$2:$A$137,A4,Raw_GHG_Emissions!$D$2:$D$137,"Scope 1",Raw_GHG_Emissions!$C$2:$C$137,"Gross emissions") -> 47050 | C4: =SUMIFS(Raw_GHG_Emissions!$F$2:$F$137,Raw_GHG_Emissions!$A$2:$A$137,A4,Raw_GHG_Emissions!$D$2:$D$137,"Scope 2 (market-based)",Raw_GHG_Emissions!$C$2:$C$137,"Gross emissions") -> 36250 | D4: =SUMIFS(Raw_GHG_Emissions!$F$2:$F$137,Raw_GHG_Emissions!$A$2:$A$137,A4,Raw_GHG_Emissions!$D$2:$D$137,"Scope 3",Raw_GHG_Emissions!$C$2:$C$137,"Gross emissions") -> 27333000 | E4: =SUM(B4:D4) -> 27416300 | F4: =SUMIFS(Raw_GHG_Emissions!$F$2:$F$137,Raw_GHG_Emissions!$A$2:$A$137,A4,Raw_GHG_Emissions!$C$2:$C$137,"Carbon removals") -> 0 | G4: =E4+F4 -> 27416300
A5: 2018 | B5: =SUMIFS(Raw_GHG_Emissions!$F$2:$F$137,Raw_GHG_Emissions!$A$2:$A$137,A5,Raw_GHG_Emissions!$D$2:$D$137,"Scope 1",Raw_GHG_Emissions!$C$2:$C$137,"Gross emissions") -> 57440 | C5: =SUMIFS(Raw_GHG_Emissions!$F$2:$F$137,Raw_GHG_Emissions!$A$2:$A$137,A5,Raw_GHG_Emissions!$D$2:$D$137,"Scope 2 (market-based)",Raw_GHG_Emissions!$C$2:$C$137,"Gross emissions") -> 8730 | D5: =SUMIFS(Raw_GHG_Emissions!$F$2:$F$137,Raw_GHG_Emissions!$A$2:$A$137,A5,Raw_GHG_Emissions!$D$2:$D$137,"Scope 3",Raw_GHG_Emissions!$C$2:$C$137,"Gross emissions") -> 25070000 | E5: =SUM(B5:D5) -> 25136170 | F5: =SUMIFS(Raw_GHG_Emissions!$F$2:$F$137,Raw_GHG_Emissions!$A$2:$A$137,A5,Raw_GHG_Emissions!$C$2:$C$137,"Carbon removals") -> 0 | G5: =E5+F5 -> 25136170
A6: 2019 | B6: =SUMIFS(Raw_GHG_Emissions!$F$2:$F$137,Raw_GHG_Emissions!$A$2:$A$137,A6,Raw_GHG_Emissions!$D$2:$D$137,"Scope 1",Raw_GHG_Emissions!$C$2:$C$137,"Gross emissions") -> 52730 | C6: =SUMIFS(Raw_GHG_Emissions!$F$2:$F$137,Raw_GHG_Emissions!$A$2:$A$137,A6,Raw_GHG_Emissions!$D$2:$D$137,"Scope 2 (market-based)",Raw_GHG_Emissions!$C$2:$C$137,"Gross emissions") -> 0 | D6: =SUMIFS(Raw_GHG_Emissions!$F$2:$F$137,Raw_GHG_Emissions!$A$2:$A$137,A6,Raw_GHG_Emissions!$D$2:$D$137,"Scope 3",Raw_GHG_Emissions!$C$2:$C$137,"Gross emissions") -> 24981000 | E6: =SUM(B6:D6) -> 25033730 | F6: =SUMIFS(Raw_GHG_Emissions!$F$2:$F$137,Raw_GHG_Emissions!$A$2:$A$137,A6,Raw_GHG_Emissions!$C$2:$C$137,"Carbon removals") -> 0 | G6: =E6+F6 -> 25033730
A7: 2020 | B7: =SUMIFS(Raw_GHG_Emissions!$F$2:$F$137,Raw_GHG_Emissions!$A$2:$A$137,A7,Raw_GHG_Emissions!$D$2:$D$137,"Scope 1",Raw_GHG_Emissions!$C$2:$C$137,"Gross emissions") -> 47440 | C7: =SUMIFS(Raw_GHG_Emissions!$F$2:$F$137,Raw_GHG_Emissions!$A$2:$A$137,A7,Raw_GHG_Emissions!$D$2:$D$137,"Scope 2 (market-based)",Raw_GHG_Emissions!$C$2:$C$137,"Gross emissions") -> 0 | D7: =SUMIFS(Raw_GHG_Emissions!$F$2:$F$137,Raw_GHG_Emissions!$A$2:$A$137,A7,Raw_GHG_Emissions!$D$2:$D$137,"Scope 3",Raw_GHG_Emissions!$C$2:$C$137,"Gross emissions") -> 22547000 | E7: =SUM(B7:D7) -> 22594440 | F7: =SUMIFS(Raw_GHG_Emissions!$F$2:$F$137,Raw_GHG_Emissions!$A$2:$A$137,A7,Raw_GHG_Emissions!$C$2:$C$137,"Carbon removals") -> -70000 | G7: =E7+F7 -> 22524440
A8: 2021 | B8: =SUMIFS(Raw_GHG_Emissions!$F$2:$F$137,Raw_GHG_Emissions!$A$2:$A$137,A8,Raw_GHG_Emissions!$D$2:$D$137,"Scope 1",Raw_GHG_Emissions!$C$2:$C$137,"Gross emissions") -> 55200 | C8: =SUMIFS(Raw_GHG_Emissions!$F$2:$F$137,Raw_GHG_Emissions!$A$2:$A$137,A8,Raw_GHG_Emissions!$D$2:$D$137,"Scope 2 (market-based)",Raw_GHG_Emissions!$C$2:$C$137,"Gross emissions") -> 2780 | D8: =SUMIFS(Raw_GHG_Emissions!$F$2:$F$137,Raw_GHG_Emissions!$A$2:$A$137,A8,Raw_GHG_Emissions!$D$2:$D$137,"Scope 3",Raw_GHG_Emissions!$C$2:$C$137,"Gross emissions") -> 23128420 | E8: =SUM(B8:D8) -> 23186400 | F8: =SUMIFS(Raw_GHG_Emissions!$F$2:$F$137,Raw_GHG_Emissions!$A$2:$A$137,A8,Raw_GHG_Emissions!$C$2:$C$137,"Carbon removals") -> -667000 | G8: =E8+F8 -> 22519400
A9: 2022 | B9: =SUMIFS(Raw_GHG_Emissions!$F$2:$F$137,Raw_GHG_Emissions!$A$2:$A$137,A9,Raw_GHG_Emissions!$D$2:$D$137,"Scope 1",Raw_GHG_Emissions!$C$2:$C$137,"Gross emissions") -> 55200 | C9: =SUMIFS(Raw_GHG_Emissions!$F$2:$F$137,Raw_GHG_Emissions!$A$2:$A$137,A9,Raw_GHG_Emissions!$D$2:$D$137,"Scope 2 (market-based)",Raw_GHG_Emissions!$C$2:$C$137,"Gross emissions") -> 3000 | D9: =SUMIFS(Raw_GHG_Emissions!$F$2:$F$137,Raw_GHG_Emissions!$A$2:$A$137,A9,Raw_GHG_Emissions!$D$2:$D$137,"Scope 3",Raw_GHG_Emissions!$C$2:$C$137,"Gross emissions") -> 20545800 | E9: =SUM(B9:D9) -> 20604000 | F9: =SUMIFS(Raw_GHG_Emissions!$F$2:$F$137,Raw_GHG_Emissions!$A$2:$A$137,A9,Raw_GHG_Emissions!$C$2:$C$137,"Carbon removals") -> -324100 | G9: =E9+F9 -> 20279900
A11: Totals computed live via SUMIFS from Raw_GHG_Emissions. Blank source cells (undisclosed sub-categories, esp. pre-2019) are treated as 0 by SUMIFS.

Sheet Carbon_Footprint_by_Product
A1: Release Year | B1: Product | C1: Baseline Storage (GB) | D1: Carbon Footprint (kg CO2e)
A2: 2023 | B2: iPhone 15 | C2: 128 | D2: 56
A3: 2022 | B3: iPhone 14 | C3: 128 | D3: 61
A4: 2021 | B4: iPhone 13 | C4: 128 | D4: 64
A5: 2020 | B5: iPhone 12 | C5: 64 | D5: 70
A6: 2019 | B6: iPhone 11 | C6: 64 | D6: 72
A7: 2018 | B7: iPhone Xs | C7: 64 | D7: 70
A8: 2017 | B8: iPhone X | C8: 64 | D8: 79
A9: 2017 | B9: iPhone 8 | C9: 64 | D9: 57
A10: 2016 | B10: iPhone 7 | C10: 32 | D10: 56
A11: 2015 | B11: iPhone 6s | C11: 32 | D11: 54

Sheet Normalizing_Factors
A1: Fiscal Year | B1: Revenue ($M) | C1: Market Capitalization ($B) | D1: Employees | E1: Emissions Intensity (Net tCO2e per $M Revenue)
A2: 2015 | B2: 233715 | C2: 580 | D2: 110000 | E2: =IFERROR(INDEX(Yearly_Scope_Summary!$G$2:$G$9,MATCH(A2,Yearly_Scope_Summary!$A$2:$A$9,0))/B2,"n/a") -> 164.23195
A3: 2016 | B3: 215639 | C3: 600 | D3: 116000 | E3: =IFERROR(INDEX(Yearly_Scope_Summary!$G$2:$G$9,MATCH(A3,Yearly_Scope_Summary!$A$2:$A$9,0))/B3,"n/a") -> 137.17078
A4: 2017 | B4: 229234 | C4: 740 | D4: 123000 | E4: =IFERROR(INDEX(Yearly_Scope_Summary!$G$2:$G$9,MATCH(A4,Yearly_Scope_Summary!$A$2:$A$9,0))/B4,"n/a") -> 119.59962
A5: 2018 | B5: 265595 | C5: 830 | D5: 132000 | E5: =IFERROR(INDEX(Yearly_Scope_Summary!$G$2:$G$9,MATCH(A5,Yearly_Scope_Summary!$A$2:$A$9,0))/B5,"n/a") -> 94.640976
A6: 2019 | B6: 260174 | C6: 1090 | D6: 137000 | E6: =IFERROR(INDEX(Yearly_Scope_Summary!$G$2:$G$9,MATCH(A6,Yearly_Scope_Summary!$A$2:$A$9,0))/B6,"n/a") -> 96.219184
A7: 2020 | B7: 274515 | C7: 1720 | D7: 147000 | E7: =IFERROR(INDEX(Yearly_Scope_Summary!$G$2:$G$9,MATCH(A7,Yearly_Scope_Summary!$A$2:$A$9,0))/B7,"n/a") -> 82.051764
A8: 2021 | B8: 365817 | C8: 2450 | D8: 154000 | E8: =IFERROR(INDEX(Yearly_Scope_Summary!$G$2:$G$9,MATCH(A8,Yearly_Scope_Summary!$A$2:$A$9,0))/B8,"n/a") -> 61.559195
A9: 2022 | B9: 394328 | C9: 2490 | D9: 164000 | E9: =IFERROR(INDEX(Yearly_Scope_Summary!$G$2:$G$9,MATCH(A9,Yearly_Scope_Summary!$A$2:$A$9,0))/B9,"n/a") -> 51.429013
A11: Intensity ratio = Net Emissions (Yearly_Scope_Summary, corporate scope only) / Revenue. Not comparable to product life-cycle totals.
